<!---->

<robot name="ba_roboter">
  <material name="orange">
    <color rgba="1.0 0.5 0.2 1" />
  </material>

  <link name="base_link">
    <visual>
      <origin xyz="0.0 0.0 0.0" rpy="0.0 0.0 0.0" />
      <geometry>
        <box size="0.5 0.5 0.1" />
      </geometry>
      <material name="orange" />
    </visual>
  </link>

  <link name="laser">
    <visual>
      <origin xyz="0.0 0.0 0.0" rpy="0.0 0.0 0.0" />
      <geometry>
        <box size="0.1 0.1 0.1" />
      </geometry>
      <material name="orange" />
    </visual>
  </link>

  <link name="velodyne">
    <visual>
      <origin  xyz="0.0 0.0 0.0" />
      <geometry>
        <box size="0.5 0.1 0.1" />
      </geometry>
      <material name="orange" />
    </visual>
  </link>

  <link name="velodyne_yaw">
    <visual>
      <origin  xyz="0.0 0.0 0.0" />
      <geometry>
        <box size="0.0 0.0 0.0" />
      </geometry>
      <material name="orange" />
    </visual>
  </link>

  <link name="imu_link">
    <visual>
      <origin xyz="0.0 0.0 0.0" />
      <geometry>
        <box size="0.0 0.0 0.0" />
      </geometry>
      <material name="orange" />
    </visual>
  </link>

  <link name="z_up_link">
    <visual>
      <origin xyz="0.0 0.0 0.0" />
      <geometry>
        <box size="0.0 0.0 0.0" />
      </geometry>
      <material name="orange" />
    </visual>
  </link>

  <link name="gps">
    <visual>
      <origin xyz="0.0 0.0 0.0" />
      <geometry>
        <box size="0.0 0.0 0.0" />
      </geometry>
      <material name="orange" />
    </visual>
  </link>

  <link name="odom">
    <visual>
      <origin xyz="0.0 0.0 0.0" />
      <geometry>
        <box size="0.5 0.3 0.1" />
      </geometry>
      <material name="orange" />
    </visual>
  </link>

  <joint name="velodyne_yaw_joint" type="fixed">
    <parent link="base_link" />
    <child link="velodyne_yaw" />
    <origin xyz="0 0 0.38" rpy=" 0.0 1.57079632679 0.0" />
  </joint>

  <joint name="velodyne_joint" type="fixed">
    <parent link="velodyne_yaw" />
    <child link="velodyne" />
    <origin xyz="0 0 0.12" rpy=" 0.0 0.0 2.09439510239" />
  </joint>

  <joint name="laser_joint" type="fixed">
    <parent link="base_link" />
    <child link="laser" />
    <origin xyz="0 0 0.5 " rpy="0.0 0.0  0.0" />
  </joint>
  
  <joint name="z_up_joint" type="fixed">
    <parent link="base_link" />
    <child link="z_up_link" />
    <origin xyz="0 0 0" rpy="0.0 0.0 0.0"/>
  </joint>
  
  <joint name="imu_joint" type="fixed">
    <parent link="z_up_link" />
    <child link="imu_link" />
    <origin xyz="0 0 0" rpy="1.60816 0.0 0.0"/>
  </joint>

  <joint name="odom_joint" type="floating">
    <parent link="odom" />
    <child link="base_link" />
    <origin xyz="0 0 0" rpy="0.0 0.0 0.0" />
  </joint>

  <joint name="gps_joint" type="fixed">
    <parent link="base_link" />
    <child link="gps" />
    <origin xyz="0 0 0" rpy="0.0 0.0 0.0" />
  </joint>


</robot>
